Workbook

Sheet Sheet2
A1: tahap_proyek_id | B1: Tahapan | C1: Deliverables | D1: order_step | E1: start | F1: end | G1: tanggal_realisasi | H1: checklist | I1: nomor | J1: status | K1: catatan | L1: created_at | M1: modified_at
A2: 23 | B2: Pra Pembangunan dan Pra Pengadaan | C2: RBT | D2: 1 | H2: 1 | J2: FINISHED
A3: 23 | B3: Pra Pembangunan dan Pra Pengadaan | C3: RPP | D3: 2 | H3: 1 | J3: FINISHED
A4: 23 | B4: Pra Pembangunan dan Pra Pengadaan | C4: RBTek | D4: 3 | H4: 1 | J4: FINISHED
A5: 23 | B5: Pengadaan - Kons. Perancang | C5: KAK | D5: 4 | H5: 1 | J5: FINISHED
A6: 23 | B6: Pengadaan - Kons. Perancang | C6: SPPP | D6: 5 | H6: 1 | J6: FINISHED
A7: 23 | B7: Pengadaan - Kons. MK | C7: KAK | D7: 6 | H7: 1 | J7: FINISHED
A8: 23 | B8: Pengadaan - Kons. MK | C8: SPPP | D8: 7 | H8: 1 | J8: FINISHED
A9: 23 | B9: Pengadaan - Kontraktor | C9: KAK | D9: 8 | H9: 1 | J9: FINISHED
A10: 23 | B10: Pengadaan - Kontraktor | C10: SPPP | D10: 9 | H10: 1 | J10: FINISHED
A11: 23 | B11: Implementasi | C11: Kick Off | D11: 10 | E11: 46023 | F11: 46082 | H11: 1 | J11: FINISHED
A12: 23 | B12: Implementasi | C12: BAST 1 | D12: 11 | E12: 46113 | F12: 46113 | G12: 46142 | H12: 1 | J12: FINISHED
A13: 23 | B13: Implementasi | C13: BAST 2 | D13: 12 | H13: 0 | J13: ON TRACK
A14: 24 | B14: Pra Pembangunan dan Pra Pengadaan | C14: RBT | D14: 1 | H14: 1 | J14: FINISHED
A15: 24 | B15: Pra Pembangunan dan Pra Pengadaan | C15: RPP | D15: 2 | E15: 46174 | F15: 46174 | G15: 46198 | H15: 1 | J15: FINISHED
A16: 24 | B16: Pra Pembangunan dan Pra Pengadaan | C16: RBTek | D16: 3 | E16: 46266 | F16: 46266 | H16: 0 | J16: ON TRACK
A17: 24 | B17: Pengadaan - Kons. Perancang | C17: KAK | D17: 4 | E17: 46054 | F17: 46235 | G17: 46132 | H17: 1 | J17: FINISHED
A18: 24 | B18: Pengadaan - Kons. Perancang | C18: SPPP | D18: 5 | H18: 1 | J18: FINISHED
A19: 24 | B19: Pengadaan - Kons. MK | C19: KAK | D19: 6 | H19: 1 | J19: FINISHED
A20: 24 | B20: Pengadaan - Kons. MK | C20: SPPP | D20: 7 | H20: 1 | J20: FINISHED
A21: 24 | B21: Pengadaan - Kontraktor | C21: KAK | D21: 8 | E21: 46266 | F21: 46327 | H21: 0 | J21: ON TRACK
A22: 24 | B22: Pengadaan - Kontraktor | C22: SPPP | D22: 9 | E22: 46357 | F22: 46357 | H22: 0 | J22: ON TRACK
A23: 24 | B23: Implementasi | C23: Kick Off | D23: 10 | H23: 0 | J23: ON TRACK
A24: 24 | B24: Implementasi | C24: BAST 1 | D24: 11 | H24: 0 | J24: ON TRACK
A25: 24 | B25: Implementasi | C25: BAST 2 | D25: 12 | H25: 0 | J25: ON TRACK
A26: 26 | B26: Pra Pembangunan dan Pra Pengadaan | C26: RPP | D26: =IF(CHECKLIST!H11<>"",CHECKLIST!H11,"") -> 4 | E26: 46296 | F26: 46296 | G26: =IF(CHECKLIST!Y11<>"",CHECKLIST!Y11,"") | H26: =IF(CHECKLIST!U11,1,0) -> 0 | I26: =IF(CHECKLIST!AB11<>"",CHECKLIST!AB11,"") | J26: =CHECKLIST!Z11 -> NOT STARTED | K26: =IF(CHECKLIST!AC11<>"",CHECKLIST!AC11,"") | L26: 46219 | M26: 46219
A27: 26 | B27: Pengadaan - Kons. MK | C27: KAK | D27: =IF(CHECKLIST!H12<>"",CHECKLIST!H12,"") -> 11 | E27: 46235 | F27: 46296 | G27: =IF(CHECKLIST!Y12<>"",CHECKLIST!Y12,"") | H27: =IF(CHECKLIST!U12,1,0) -> 0 | I27: =IF(CHECKLIST!AB12<>"",CHECKLIST!AB12,"") | J27: =CHECKLIST!Z12 -> BEHIND | K27: =IF(CHECKLIST!AC12<>"",CHECKLIST!AC12,"") | L27: 46219 | M27: 46219
A28: 26 | B28: Pengadaan - Kons. MK | C28: SPPP | D28: =IF(CHECKLIST!H13<>"",CHECKLIST!H13,"") -> 12 | E28: 46327 | F28: 46357 | G28: =IF(CHECKLIST!Y13<>"",CHECKLIST!Y13,"") | H28: =IF(CHECKLIST!U13,1,0) -> 0 | I28: =IF(CHECKLIST!AB13<>"",CHECKLIST!AB13,"") | J28: =CHECKLIST!Z13 -> NOT STARTED | K28: =IF(CHECKLIST!AC13<>"",CHECKLIST!AC13,"") | L28: 46219 | M28: 46219
A29: 73 | B29: Pengadaan - Kontraktor | C29: KAK | D29: =IF(CHECKLIST!H14<>"",CHECKLIST!H14,"") -> 7 | E29: 46174 | F29: 46266 | G29: =IF(CHECKLIST!Y14<>"",CHECKLIST!Y14,"") -> 46178 | H29: =IF(CHECKLIST!U14,1,0) -> 1 | I29: =IF(CHECKLIST!AB14<>"",CHECKLIST!AB14,"") -> 27/65/DPAN-GPAN1/M.01/B | J29: =CHECKLIST!Z14 -> ON TRACK | K29: =IF(CHECKLIST!AC14<>"",CHECKLIST!AC14,"") | L29: 46219 | M29: 46219
A30: 73 | B30: Pengadaan - Kontraktor | C30: SPPP | D30: =IF(CHECKLIST!H15<>"",CHECKLIST!H15,"") -> 8 | E30: 46296 | F30: 46296 | G30: =IF(CHECKLIST!Y15<>"",CHECKLIST!Y15,"") | H30: =IF(CHECKLIST!U15,1,0) -> 1 | I30: =IF(CHECKLIST!AB15<>"",CHECKLIST!AB15,"") | J30: =CHECKLIST!Z15 -> AHEAD | K30: =IF(CHECKLIST!AC15<>"",CHECKLIST!AC15,"") -> Adendum kontrak payung Tahap 2A | L30: 46219 | M30: 46219
A31: 73 | B31: Implementasi | C31: Pembangunan Fisik | D31: =IF(CHECKLIST!H16<>"",CHECKLIST!H16,"") -> 1 | E31: 46327 | F31: 46327 | G31: =IF(CHECKLIST!Y16<>"",CHECKLIST!Y16,"") | H31: =IF(CHECKLIST!U16,1,0) -> 0 | I31: =IF(CHECKLIST!AB16<>"",CHECKLIST!AB16,"") | J31: =CHECKLIST!Z16 -> NOT STARTED | K31: =IF(CHECKLIST!AC16<>"",CHECKLIST!AC16,"") | L31: 46219 | M31: 46219
A32: 73 | B32: Implementasi | C32: BAST 1 | D32: =IF(CHECKLIST!H17<>"",CHECKLIST!H17,"") -> 2 | E32: 46357 | F32: 46357 | G32: =IF(CHECKLIST!Y17<>"",CHECKLIST!Y17,"") | H32: =IF(CHECKLIST!U17,1,0) -> 0 | I32: =IF(CHECKLIST!AB17<>"",CHECKLIST!AB17,"") | J32: =CHECKLIST!Z17 -> NOT STARTED | K32: =IF(CHECKLIST!AC17<>"",CHECKLIST!AC17,"") | L32: 46219 | M32: 46219
A33: 34 | B33: Pra Pembangunan dan Pra Pengadaan | C33: RBT | D33: 1 | H33: 1 | J33: FINISHED
A34: 34 | B34: Pra Pembangunan dan Pra Pengadaan | C34: RPP | D34: 2 | H34: 1 | J34: FINISHED
A35: 34 | B35: Pra Pembangunan dan Pra Pengadaan | C35: RBTek | D35: 3 | H35: 1 | J35: FINISHED
A36: 34 | B36: Pengadaan - Kons. Perancang | C36: KAK | D36: 4 | H36: 1 | J36: FINISHED
A37: 34 | B37: Pengadaan - Kons. Perancang | C37: SPPP | D37: 5 | H37: 1 | J37: FINISHED
A38: 34 | B38: Pengadaan - Kons. MK | C38: KAK | D38: 6 | H38: 1 | J38: FINISHED
A39: 34 | B39: Pengadaan - Kons. MK | C39: SPPP | D39: 7 | H39: 1 | J39: FINISHED
A40: 34 | B40: Pengadaan - Kontraktor | C40: KAK | D40: 8 | H40: 1 | J40: FINISHED
...

Sheet CHECKLIST
I1: Current Date : | O1: =TODAY() -> 46268
A2: No | B2: Nama Proyek | C2: Tahap | D2: UKER | E2: Tahapan | F2: Deliverables | I2: Q1 | L2: Q2 | O2: Q3 | R2: Q4 | U2: Checklist | V2: Start | W2: End | X2: Quarter | Y2: Realisasi (Date) | Z2: Tracker | AA2: Nomor Kontrak | AB2: Nomor | AC2: Note | AE2: Legend | AF2: Color | AG2: Code
I3: =DATE(2026,1,1) -> 46023 | J3: =EDATE(I3,1) -> 46054 | K3: =EDATE(J3,1) -> 46082 | L3: =EDATE(K3,1) -> 46113 | M3: =EDATE(L3,1) -> 46143 | N3: =EDATE(M3,1) -> 46174 | O3: =EDATE(N3,1) -> 46204 | P3: =EDATE(O3,1) -> 46235 | Q3: =EDATE(P3,1) -> 46266 | ... T3: =EDATE(S3,1) -> 46357
A4: 1 | B4: Modern Office | C4: 2A | D4: GPAN1 | E4: Implementasi | F4: Pembangunan Fisik | G4: {=E4:E129 & " | " & F4:F129} -> Implementasi | Pembangunan Fisik | H4: {=IFERROR(_xlfn.XLOOKUP(G4:G129, $AE$4:$AE$19, $AG$4:$AG$19), "")} -> 1 | I4: =IF(AND(I$3 >= $V4, I$3 <= $W4), $H4, "") -> 1 | J4: =IF(AND(J$3 >= $V4, J$3 <= $W4), $H4, "") -> 1 | K4: =IF(AND(K$3 >= $V4, K$3 <= $W4), $H4, "") -> 1 | L4: =IF(AND(L$3 >= $V4, L$3 <= $W4), $H4, "") | M4: =IF(AND(M$3 >= $V4, M$3 <= $W4), $H4, "") | N4: =IF(AND(N$3 >= $V4, N$3 <= $W4), $H4, "") | O4: =IF(AND(O$3 >= $V4, O$3 <= $W4), $H4, "") | P4: =IF(AND(P$3 >= $V4, P$3 <= $W4), $H4, "") | ... T4: =IF(AND(T$3 >= $V4, T$3 <= $W4), $H4, "") | U4: TRUE | V4: 46023 | W4: 46082 | X4: Q1 | Y4: 46021 | Z4: {=IFERROR( IF(V4:V129="", "", IF(U4:U129=TRUE, IF(TODAY()<V4:V129, "AHEAD", "ON TRACK"), IF( TODAY() > (DATE(YEAR(V4:V129), MONTH(V4:V129)+1, 1)-1), "BEHIND", IF(TODAY()>=V4:V129, "ON TRACK", "NOT STARTED") ) ) ), "")} -> ON TRACK | AE4: Implementasi | Pembangunan Fisik | AG4: 1
A5: 2 | B5: Modern Office | C5: 2A | D5: GPAN1 | E5: Implementasi | F5: BAST 1 | G5: Implementasi | BAST 1 | H5: 2 | I5: =IF(AND(I$3 >= $V5, I$3 <= $W5), $H5, "") | J5: =IF(AND(J$3 >= $V5, J$3 <= $W5), $H5, "") | K5: =IF(AND(K$3 >= $V5, K$3 <= $W5), $H5, "") | L5: =IF(AND(L$3 >= $V5, L$3 <= $W5), $H5, "") -> 2 | M5: =IF(AND(M$3 >= $V5, M$3 <= $W5), $H5, "") | N5: =IF(AND(N$3 >= $V5, N$3 <= $W5), $H5, "") | O5: =IF(AND(O$3 >= $V5, O$3 <= $W5), $H5, "") | P5: =IF(AND(P$3 >= $V5, P$3 <= $W5), $H5, "") | ... T5: =IF(AND(T$3 >= $V5, T$3 <= $W5), $H5, "") | U5: TRUE | V5: 46113 | W5: 46113 | X5: Q1 | Y5: 46142 | Z5: ON TRACK | AE5: Implementasi | BAST 1 | AG5: 2
A6: 3 | B6: Modern Office | C6: 2B & 2C | D6: GPAN2 | E6: Pra Pembangunan dan Pra Pengadaan | F6: RPP | G6: Pra Pembangunan dan Pra Pengadaan | RPP | H6: 4 | I6: =IF(AND(I$3 >= $V6, I$3 <= $W6), $H6, "") | J6: =IF(AND(J$3 >= $V6, J$3 <= $W6), $H6, "") | K6: =IF(AND(K$3 >= $V6, K$3 <= $W6), $H6, "") | L6: =IF(AND(L$3 >= $V6, L$3 <= $W6), $H6, "") | M6: =IF(AND(M$3 >= $V6, M$3 <= $W6), $H6, "") | N6: =IF(AND(N$3 >= $V6, N$3 <= $W6), $H6, "") -> 4 | O6: =IF(AND(O$3 >= $V6, O$3 <= $W6), $H6, "") | P6: =IF(AND(P$3 >= $V6, P$3 <= $W6), $H6, "") | ... T6: =IF(AND(T$3 >= $V6, T$3 <= $W6), $H6, "") | U6: TRUE | V6: 46174 | W6: 46174 | X6: Q1 | Y6: 46198 | Z6: ON TRACK | AE6: Implementasi | SLO / SLF / BAPP | AG6: 3
A7: 4 | B7: Modern Office | C7: 2B & 2C | D7: GPAN2 | E7: Pra Pembangunan dan Pra Pengadaan | F7: RBTek | G7: Pra Pembangunan dan Pra Pengadaan | RBTek | H7: 6 | I7: =IF(AND(I$3 >= $V7, I$3 <= $W7), $H7, "") | J7: =IF(AND(J$3 >= $V7, J$3 <= $W7), $H7, "") | K7: =IF(AND(K$3 >= $V7, K$3 <= $W7), $H7, "") | L7: =IF(AND(L$3 >= $V7, L$3 <= $W7), $H7, "") | M7: =IF(AND(M$3 >= $V7, M$3 <= $W7), $H7, "") | N7: =IF(AND(N$3 >= $V7, N$3 <= $W7), $H7, "") | O7: =IF(AND(O$3 >= $V7, O$3 <= $W7), $H7, "") | P7: =IF(AND(P$3 >= $V7, P$3 <= $W7), $H7, "") | ... T7: =IF(AND(T$3 >= $V7, T$3 <= $W7), $H7, "") | U7: TRUE | V7: 46266 | W7: 46266 | X7: Q1 | Y7: 46246 | Z7: ON TRACK | AE7: Pra Pembangunan dan Pra Pengadaan | RPP | AG7: 4
A8: 5 | B8: Modern Office | C8: 2B & 2C | D8: GPAN2 | E8: Pengadaan - Kontraktor | F8: KAK | G8: Pengadaan - Kontraktor | KAK | H8: 7 | I8: =IF(AND(I$3 >= $V8, I$3 <= $W8), $H8, "") | J8: =IF(AND(J$3 >= $V8, J$3 <= $W8), $H8, "") | K8: =IF(AND(K$3 >= $V8, K$3 <= $W8), $H8, "") | L8: =IF(AND(L$3 >= $V8, L$3 <= $W8), $H8, "") | M8: =IF(AND(M$3 >= $V8, M$3 <= $W8), $H8, "") | N8: =IF(AND(N$3 >= $V8, N$3 <= $W8), $H8, "") | O8: =IF(AND(O$3 >= $V8, O$3 <= $W8), $H8, "") | P8: =IF(AND(P$3 >= $V8, P$3 <= $W8), $H8, "") | ... T8: =IF(AND(T$3 >= $V8, T$3 <= $W8), $H8, "") | U8: TRUE | V8: 46266 | W8: 46327 | X8: Q1 | Y8: 46246 | Z8: ON TRACK | AE8: Pra Pembangunan dan Pra Pengadaan | RBT | AG8: 5
A9: 6 | B9: Modern Office | C9: 2B & 2C | D9: GPAN2 | E9: Pengadaan - Kons. Perancang | F9: SPPP | G9: Pengadaan - Kons. Perancang | SPPP | H9: 10 | I9: =IF(AND(I$3 >= $V9, I$3 <= $W9), $H9, "") | J9: =IF(AND(J$3 >= $V9, J$3 <= $W9), $H9, "") -> 10 | K9: =IF(AND(K$3 >= $V9, K$3 <= $W9), $H9, "") -> 10 | L9: =IF(AND(L$3 >= $V9, L$3 <= $W9), $H9, "") -> 10 | M9: =IF(AND(M$3 >= $V9, M$3 <= $W9), $H9, "") -> 10 | N9: =IF(AND(N$3 >= $V9, N$3 <= $W9), $H9, "") -> 10 | O9: =IF(AND(O$3 >= $V9, O$3 <= $W9), $H9, "") -> 10 | P9: =IF(AND(P$3 >= $V9, P$3 <= $W9), $H9, "") -> 10 | ... T9: =IF(AND(T$3 >= $V9, T$3 <= $W9), $H9, "") | U9: TRUE | V9: 46054 | W9: 46235 | X9: Q1 | Y9: 46132 | Z9: ON TRACK | AA9: 28/284/DMAP/P/B | AB9: 28/160/DMAP/-GPPS-PBS/Srt/B | AC9: Kick Off: 24 Apr 2026 PT Desain Paramitra Indonesia (gd. C, D & tipikal) | AE9: Pra Pembangunan dan Pra Pengadaan | RBTek | AG9: 6
A10: 7 | B10: Modern Office | C10: 2B & 2C | D10: GPAN2 | E10: Pengadaan - Kontraktor | F10: SPPP | G10: Pengadaan - Kontraktor | SPPP | H10: 8 | I10: =IF(AND(I$3 >= $V10, I$3 <= $W10), $H10, "") | J10: =IF(AND(J$3 >= $V10, J$3 <= $W10), $H10, "") | K10: =IF(AND(K$3 >= $V10, K$3 <= $W10), $H10, "") | L10: =IF(AND(L$3 >= $V10, L$3 <= $W10), $H10, "") | M10: =IF(AND(M$3 >= $V10, M$3 <= $W10), $H10, "") | N10: =IF(AND(N$3 >= $V10, N$3 <= $W10), $H10, "") | O10: =IF(AND(O$3 >= $V10, O$3 <= $W10), $H10, "") | P10: =IF(AND(P$3 >= $V10, P$3 <= $W10), $H10, "") | ... T10: =IF(AND(T$3 >= $V10, T$3 <= $W10), $H10, "") -> 8 | U10: FALSE | V10: 46357 | W10: 46357 | X10: Q1 | Z10: NOT STARTED | AE10: Pengadaan - Kontraktor | KAK | AG10: 7
A11: 8 | B11: Modern Office | C11: 3A | D11: GPAN1 | E11: Pra Pembangunan dan Pra Pengadaan | F11: RPP | G11: Pra Pembangunan dan Pra Pengadaan | RPP | H11: 4 | I11: =IF(AND(I$3 >= $V11, I$3 <= $W11), $H11, "") | J11: =IF(AND(J$3 >= $V11, J$3 <= $W11), $H11, "") | K11: =IF(AND(K$3 >= $V11, K$3 <= $W11), $H11, "") | L11: =IF(AND(L$3 >= $V11, L$3 <= $W11), $H11, "") | M11: =IF(AND(M$3 >= $V11, M$3 <= $W11), $H11, "") | N11: =IF(AND(N$3 >= $V11, N$3 <= $W11), $H11, "") | O11: =IF(AND(O$3 >= $V11, O$3 <= $W11), $H11, "") | P11: =IF(AND(P$3 >= $V11, P$3 <= $W11), $H11, "") | ... T11: =IF(AND(T$3 >= $V11, T$3 <= $W11), $H11, "") | U11: FALSE | V11: 46296 | W11: 46296 | X11: Q3 | Z11: NOT STARTED | AE11: Pengadaan - Kontraktor | SPPP | AG11: 8
A12: 9 | B12: Modern Office | C12: 3A | D12: GPAN1 | E12: Pengadaan - Kons. MK | F12: KAK | G12: Pengadaan - Kons. MK | KAK | H12: 11 | I12: =IF(AND(I$3 >= $V12, I$3 <= $W12), $H12, "") | J12: =IF(AND(J$3 >= $V12, J$3 <= $W12), $H12, "") | K12: =IF(AND(K$3 >= $V12, K$3 <= $W12), $H12, "") | L12: =IF(AND(L$3 >= $V12, L$3 <= $W12), $H12, "") | M12: =IF(AND(M$3 >= $V12, M$3 <= $W12), $H12, "") | N12: =IF(AND(N$3 >= $V12, N$3 <= $W12), $H12, "") | O12: =IF(AND(O$3 >= $V12, O$3 <= $W12), $H12, "") | P12: =IF(AND(P$3 >= $V12, P$3 <= $W12), $H12, "") -> 11 | ... T12: =IF(AND(T$3 >= $V12, T$3 <= $W12), $H12, "") | U12: FALSE | V12: 46235 | W12: 46296 | X12: Q3 | Z12: BEHIND | AE12: Pengadaan - Kons. Perancang | KAK | AG12: 9
A13: 10 | B13: Modern Office | C13: 3A | D13: GPAN1 | E13: Pengadaan - Kons. MK | F13: SPPP | G13: Pengadaan - Kons. MK | SPPP | H13: 12 | I13: =IF(AND(I$3 >= $V13, I$3 <= $W13), $H13, "") | J13: =IF(AND(J$3 >= $V13, J$3 <= $W13), $H13, "") | K13: =IF(AND(K$3 >= $V13, K$3 <= $W13), $H13, "") | L13: =IF(AND(L$3 >= $V13, L$3 <= $W13), $H13, "") | M13: =IF(AND(M$3 >= $V13, M$3 <= $W13), $H13, "") | N13: =IF(AND(N$3 >= $V13, N$3 <= $W13), $H13, "") | O13: =IF(AND(O$3 >= $V13, O$3 <= $W13), $H13, "") | P13: =IF(AND(P$3 >= $V13, P$3 <= $W13), $H13, "") | ... T13: =IF(AND(T$3 >= $V13, T$3 <= $W13), $H13, "") -> 12 | U13: FALSE | V13: 46327 | W13: 46357 | X13: Q3 | Z13: NOT STARTED | AE13: Pengadaan - Kons. Perancang | SPPP | AG13: 10
A14: 11 | B14: Perkuatan Struktur Gedung KOPERBI Thamrin | C14: 2B & 2C | D14: GPAN1 | E14: Pengadaan - Kontraktor | F14: KAK | G14: Pengadaan - Kontraktor | KAK | H14: 7 | I14: =IF(AND(I$3 >= $V14, I$3 <= $W14), $H14, "") | J14: =IF(AND(J$3 >= $V14, J$3 <= $W14), $H14, "") | K14: =IF(AND(K$3 >= $V14, K$3 <= $W14), $H14, "") | L14: =IF(AND(L$3 >= $V14, L$3 <= $W14), $H14, "") | M14: =IF(AND(M$3 >= $V14, M$3 <= $W14), $H14, "") | N14: =IF(AND(N$3 >= $V14, N$3 <= $W14), $H14, "") -> 7 | O14: =IF(AND(O$3 >= $V14, O$3 <= $W14), $H14, "") -> 7 | P14: =IF(AND(P$3 >= $V14, P$3 <= $W14), $H14, "") -> 7 | ... T14: =IF(AND(T$3 >= $V14, T$3 <= $W14), $H14, "") | U14: TRUE | V14: 46174 | W14: 46266 | X14: Q2 | Y14: 46178 | Z14: ON TRACK | AB14: 27/65/DPAN-GPAN1/M.01/B | AE14: Pengadaan - Kons. MK | KAK | AG14: 11
A15: 12 | B15: Perkuatan Struktur Gedung KOPERBI Thamrin | C15: 2B & 2C | D15: GPAN1 | E15: Pengadaan - Kontraktor | F15: SPPP | G15: Pengadaan - Kontraktor | SPPP | H15: 8 | I15: =IF(AND(I$3 >= $V15, I$3 <= $W15), $H15, "") | J15: =IF(AND(J$3 >= $V15, J$3 <= $W15), $H15, "") | K15: =IF(AND(K$3 >= $V15, K$3 <= $W15), $H15, "") | L15: =IF(AND(L$3 >= $V15, L$3 <= $W15), $H15, "") | M15: =IF(AND(M$3 >= $V15, M$3 <= $W15), $H15, "") | N15: =IF(AND(N$3 >= $V15, N$3 <= $W15), $H15, "") | O15: =IF(AND(O$3 >= $V15, O$3 <= $W15), $H15, "") | P15: =IF(AND(P$3 >= $V15, P$3 <= $W15), $H15, "") | ... T15: =IF(AND(T$3 >= $V15, T$3 <= $W15), $H15, "") | U15: TRUE | V15: 46296 | W15: 46296 | X15: Q2 | Z15: AHEAD | AC15: Adendum kontrak payung Tahap 2A | AE15: Pengadaan - Kons. MK | SPPP | AG15: 12
A16: 13 | B16: Perkuatan Struktur Gedung KOPERBI Thamrin | C16: 2B & 2C | D16: GPAN1 | E16: Implementasi | F16: Pembangunan Fisik | G16: Implementasi | Pembangunan Fisik | H16: 1 | I16: =IF(AND(I$3 >= $V16, I$3 <= $W16), $H16, "") | J16: =IF(AND(J$3 >= $V16, J$3 <= $W16), $H16, "") | K16: =IF(AND(K$3 >= $V16, K$3 <= $W16), $H16, "") | L16: =IF(AND(L$3 >= $V16, L$3 <= $W16), $H16, "") | M16: =IF(AND(M$3 >= $V16, M$3 <= $W16), $H16, "") | N16: =IF(AND(N$3 >= $V16, N$3 <= $W16), $H16, "") | O16: =IF(AND(O$3 >= $V16, O$3 <= $W16), $H16, "") | P16: =IF(AND(P$3 >= $V16, P$3 <= $W16), $H16, "") | ... T16: =IF(AND(T$3 >= $V16, T$3 <= $W16), $H16, "") | U16: FALSE | V16: 46327 | W16: 46327 | X16: Q2 | Z16: NOT STARTED | AE16: Pengadaan - Lahan | KAK | AG16: 13
A17: 14 | B17: Perkuatan Struktur Gedung KOPERBI Thamrin | C17: 2B & 2C | D17: GPAN1 | E17: Implementasi | F17: BAST 1 | G17: Implementasi | BAST 1 | H17: 2 | I17: =IF(AND(I$3 >= $V17, I$3 <= $W17), $H17, "") | J17: =IF(AND(J$3 >= $V17, J$3 <= $W17), $H17, "") | K17: =IF(AND(K$3 >= $V17, K$3 <= $W17), $H17, "") | L17: =IF(AND(L$3 >= $V17, L$3 <= $W17), $H17, "") | M17: =IF(AND(M$3 >= $V17, M$3 <= $W17), $H17, "") | N17: =IF(AND(N$3 >= $V17, N$3 <= $W17), $H17, "") | O17: =IF(AND(O$3 >= $V17, O$3 <= $W17), $H17, "") | P17: =IF(AND(P$3 >= $V17, P$3 <= $W17), $H17, "") | ... T17: =IF(AND(T$3 >= $V17, T$3 <= $W17), $H17, "") -> 2 | U17: FALSE | V17: 46357 | W17: 46357 | X17: Q2 | Z17: NOT STARTED | AE17: Pengadaan - Lahan | AJB | AG17: 14
A18: 15 | B18: Fasilitas Akomodasi KOPERBI SINERGI | C18: 1 | D18: GPAN2 | E18: Implementasi | F18: Pembangunan Fisik | G18: Implementasi | Pembangunan Fisik | H18: 1 | I18: =IF(AND(I$3 >= $V18, I$3 <= $W18), $H18, "") -> 1 | J18: =IF(AND(J$3 >= $V18, J$3 <= $W18), $H18, "") -> 1 | K18: =IF(AND(K$3 >= $V18, K$3 <= $W18), $H18, "") -> 1 | L18: =IF(AND(L$3 >= $V18, L$3 <= $W18), $H18, "") -> 1 | M18: =IF(AND(M$3 >= $V18, M$3 <= $W18), $H18, "") -> 1 | N18: =IF(AND(N$3 >= $V18, N$3 <= $W18), $H18, "") -> 1 | O18: =IF(AND(O$3 >= $V18, O$3 <= $W18), $H18, "") -> 1 | P18: =IF(AND(P$3 >= $V18, P$3 <= $W18), $H18, "") -> 1 | ... T18: =IF(AND(T$3 >= $V18, T$3 <= $W18), $H18, "") | U18: TRUE | V18: 46023 | W18: 46327 | X18: Q1 | Z18: ON TRACK | AE18: =G115 -> Pra Pembangunan dan Pra Pengadaan | RPP | AG18: 15
A19: 16 | B19: Fasilitas Akomodasi KOPERBI SINERGI | C19: 1 | D19: GPAN2 | E19: Implementasi | F19: SLO / SLF / BAPP | G19: Implementasi | SLO / SLF / BAPP | H19: 3 | I19: =IF(AND(I$3 >= $V19, I$3 <= $W19), $H19, "") | J19: =IF(AND(J$3 >= $V19, J$3 <= $W19), $H19, "") | K19: =IF(AND(K$3 >= $V19, K$3 <= $W19), $H19, "") | L19: =IF(AND(L$3 >= $V19, L$3 <= $W19), $H19, "") | M19: =IF(AND(M$3 >= $V19, M$3 <= $W19), $H19, "") | N19: =IF(AND(N$3 >= $V19, N$3 <= $W19), $H19, "") | O19: =IF(AND(O$3 >= $V19, O$3 <= $W19), $H19, "") | P19: =IF(AND(P$3 >= $V19, P$3 <= $W19), $H19, "") | ... T19: =IF(AND(T$3 >= $V19, T$3 <= $W19), $H19, "") -> 3 | U19: FALSE | V19: 46357 | W19: 46357 | X19: Q1 | Z19: NOT STARTED | AE19: =G116 -> Pengadaan - Lahan | KAK | AG19: 16
A20: 17 | B20: Fasilitas Akomodasi KOPERBI SINERGI | C20: 1 | D20: GPAN2 | E20: Implementasi | F20: BAST 1 | G20: Implementasi | BAST 1 | H20: 2 | I20: =IF(AND(I$3 >= $V20, I$3 <= $W20), $H20, "") | J20: =IF(AND(J$3 >= $V20, J$3 <= $W20), $H20, "") | K20: =IF(AND(K$3 >= $V20, K$3 <= $W20), $H20, "") | L20: =IF(AND(L$3 >= $V20, L$3 <= $W20), $H20, "") | M20: =IF(AND(M$3 >= $V20, M$3 <= $W20), $H20, "") | N20: =IF(AND(N$3 >= $V20, N$3 <= $W20), $H20, "") | O20: =IF(AND(O$3 >= $V20, O$3 <= $W20), $H20, "") | P20: =IF(AND(P$3 >= $V20, P$3 <= $W20), $H20, "") | ... T20: =IF(AND(T$3 >= $V20, T$3 <= $W20), $H20, "") -> 2 | U20: FALSE | V20: 46357 | W20: 46357 | X20: Q1 | Z20: NOT STARTED
A21: 18 | B21: Pembangunan Gd. E & Taman Cinta Ilmu | C21: 1 | D21: GPAN1 | E21: Pra Pembangunan dan Pra Pengadaan | F21: RBT | G21: Pra Pembangunan dan Pra Pengadaan | RBT | H21: 5 | I21: =IF(AND(I$3 >= $V21, I$3 <= $W21), $H21, "") | J21: =IF(AND(J$3 >= $V21, J$3 <= $W21), $H21, "") | K21: =IF(AND(K$3 >= $V21, K$3 <= $W21), $H21, "") | L21: =IF(AND(L$3 >= $V21, L$3 <= $W21), $H21, "") | M21: =IF(AND(M$3 >= $V21, M$3 <= $W21), $H21, "") | N21: =IF(AND(N$3 >= $V21, N$3 <= $W21), $H21, "") -> 5 | O21: =IF(AND(O$3 >= $V21, O$3 <= $W21), $H21, "") | P21: =IF(AND(P$3 >= $V21, P$3 <= $W21), $H21, "") | ... T21: =IF(AND(T$3 >= $V21, T$3 <= $W21), $H21, "") | U21: TRUE | V21: 46174 | W21: 46174 | X21: Q1 | Y21: 46212 | Z21: ON TRACK | AC21: RBT akan sama dengan fasos dan cafetaria
A22: 19 | B22: Pembangunan Gd. E & Taman Cinta Ilmu | C22: 1 | D22: GPAN1 | E22: Pra Pembangunan dan Pra Pengadaan | F22: RPP | G22: Pra Pembangunan dan Pra Pengadaan | RPP | H22: 4 | I22: =IF(AND(I$3 >= $V22, I$3 <= $W22), $H22, "") | J22: =IF(AND(J$3 >= $V22, J$3 <= $W22), $H22, "") | K22: =IF(AND(K$3 >= $V22, K$3 <= $W22), $H22, "") | L22: =IF(AND(L$3 >= $V22, L$3 <= $W22), $H22, "") | M22: =IF(AND(M$3 >= $V22, M$3 <= $W22), $H22, "") | N22: =IF(AND(N$3 >= $V22, N$3 <= $W22), $H22, "") | O22: =IF(AND(O$3 >= $V22, O$3 <= $W22), $H22, "") | P22: =IF(AND(P$3 >= $V22, P$3 <= $W22), $H22, "") | ... T22: =IF(AND(T$3 >= $V22, T$3 <= $W22), $H22, "") | U22: TRUE | V22: 46266 | W22: 46266 | X22: Q1 | Y22: 46231 | Z22: ON TRACK
A23: 20 | B23: Pembangunan Gd. E & Taman Cinta Ilmu | C23: 1 | D23: GPAN1 | E23: Pra Pembangunan dan Pra Pengadaan | F23: RBTek | G23: Pra Pembangunan dan Pra Pengadaan | RBTek | H23: 6 | I23: =IF(AND(I$3 >= $V23, I$3 <= $W23), $H23, "") | J23: =IF(AND(J$3 >= $V23, J$3 <= $W23), $H23, "") | K23: =IF(AND(K$3 >= $V23, K$3 <= $W23), $H23, "") | L23: =IF(AND(L$3 >= $V23, L$3 <= $W23), $H23, "") | M23: =IF(AND(M$3 >= $V23, M$3 <= $W23), $H23, "") | N23: =IF(AND(N$3 >= $V23, N$3 <= $W23), $H23, "") | O23: =IF(AND(O$3 >= $V23, O$3 <= $W23), $H23, "") | P23: =IF(AND(P$3 >= $V23, P$3 <= $W23), $H23, "") | ... T23: =IF(AND(T$3 >= $V23, T$3 <= $W23), $H23, "") | U23: FALSE | V23: 46296 | W23: 46296 | X23: Q1 | Z23: NOT STARTED
A24: 21 | B24: Pembangunan Gd. E & Taman Cinta Ilmu | C24: 1 | D24: GPAN1 | E24: Pengadaan - Kons. MK | F24: KAK | G24: Pengadaan - Kons. MK | KAK | H24: 11 | I24: =IF(AND(I$3 >= $V24, I$3 <= $W24), $H24, "") | J24: =IF(AND(J$3 >= $V24, J$3 <= $W24), $H24, "") | K24: =IF(AND(K$3 >= $V24, K$3 <= $W24), $H24, "") | L24: =IF(AND(L$3 >= $V24, L$3 <= $W24), $H24, "") | M24: =IF(AND(M$3 >= $V24, M$3 <= $W24), $H24, "") -> 11 | N24: =IF(AND(N$3 >= $V24, N$3 <= $W24), $H24, "") -> 11 | O24: =IF(AND(O$3 >= $V24, O$3 <= $W24), $H24, "") -> 11 | P24: =IF(AND(P$3 >= $V24, P$3 <= $W24), $H24, "") | ... T24: =IF(AND(T$3 >= $V24, T$3 <= $W24), $H24, "") | U24: TRUE | V24: 46143 | W24: 46204 | X24: Q1 | Y24: 46122 | Z24: ON TRACK | AB24: 28/62/DPAN-GPAN1/M.01/B | AC24: Gabung Fasos & Gd. E
A25: 22 | B25: Pembangunan Gd. E & Taman Cinta Ilmu | C25: 1 | D25: GPAN1 | E25: Pengadaan - Kontraktor | F25: KAK | G25: Pengadaan - Kontraktor | KAK | H25: 7 | I25: =IF(AND(I$3 >= $V25, I$3 <= $W25), $H25, "") | J25: =IF(AND(J$3 >= $V25, J$3 <= $W25), $H25, "") | K25: =IF(AND(K$3 >= $V25, K$3 <= $W25), $H25, "") | L25: =IF(AND(L$3 >= $V25, L$3 <= $W25), $H25, "") | M25: =IF(AND(M$3 >= $V25, M$3 <= $W25), $H25, "") | N25: =IF(AND(N$3 >= $V25, N$3 <= $W25), $H25, "") | O25: =IF(AND(O$3 >= $V25, O$3 <= $W25), $H25, "") | P25: =IF(AND(P$3 >= $V25, P$3 <= $W25), $H25, "") | ... T25: =IF(AND(T$3 >= $V25, T$3 <= $W25), $H25, "") -> 7 | U25: FALSE | V25: 46296 | W25: 46357 | X25: Q1 | Z25: NOT STARTED
A26: 23 | B26: Pembangunan Gd. E & Taman Cinta Ilmu | C26: 1 | D26: GPAN1 | E26: Pengadaan - Kons. Perancang | F26: SPPP | G26: Pengadaan - Kons. Perancang | SPPP | H26: 10 | I26: =IF(AND(I$3 >= $V26, I$3 <= $W26), $H26, "") | J26: =IF(AND(J$3 >= $V26, J$3 <= $W26), $H26, "") | K26: =IF(AND(K$3 >= $V26, K$3 <= $W26), $H26, "") | L26: =IF(AND(L$3 >= $V26, L$3 <= $W26), $H26, "") -> 10 | M26: =IF(AND(M$3 >= $V26, M$3 <= $W26), $H26, "") -> 10 | N26: =IF(AND(N$3 >= $V26, N$3 <= $W26), $H26, "") -> 10 | O26: =IF(AND(O$3 >= $V26, O$3 <= $W26), $H26, "") -> 10 | P26: =IF(AND(P$3 >= $V26, P$3 <= $W26), $H26, "") -> 10 | ... T26: =IF(AND(T$3 >= $V26, T$3 <= $W26), $H26, "") | U26: TRUE | V26: 46113 | W26: 46296 | X26: Q1 | Y26: 46128 | Z26: ON TRACK | AB26: 28/45/DMAP-GPPS/Srt/B | AC26: Kick Off: 17 Apr 2026
A27: 24 | B27: Pembangunan Gd. E & Taman Cinta Ilmu | C27: 1 | D27: GPAN1 | E27: Pengadaan - Kons. MK | F27: SPPP | G27: Pengadaan - Kons. MK | SPPP | H27: 12 | I27: =IF(AND(I$3 >= $V27, I$3 <= $W27), $H27, "") | J27: =IF(AND(J$3 >= $V27, J$3 <= $W27), $H27, "") | K27: =IF(AND(K$3 >= $V27, K$3 <= $W27), $H27, "") | L27: =IF(AND(L$3 >= $V27, L$3 <= $W27), $H27, "") | M27: =IF(AND(M$3 >= $V27, M$3 <= $W27), $H27, "") | N27: =IF(AND(N$3 >= $V27, N$3 <= $W27), $H27, "") | O27: =IF(AND(O$3 >= $V27, O$3 <= $W27), $H27, "") | P27: =IF(AND(P$3 >= $V27, P$3 <= $W27), $H27, "") -> 12 | ... T27: =IF(AND(T$3 >= $V27, T$3 <= $W27), $H27, "") | U27: TRUE | V27: 46235 | W27: 46235 | X27: Q1 | Y27: 46225 | Z27: ON TRACK
A28: 25 | B28: Pembangunan Cafetaria, Nursery, dan Taman Cinta Keluarga | C28: 1 | D28: GPAN2 | E28: Pra Pembangunan dan Pra Pengadaan | F28: RBT | G28: Pra Pembangunan dan Pra Pengadaan | RBT | H28: 5 | I28: =IF(AND(I$3 >= $V28, I$3 <= $W28), $H28, "") | J28: =IF(AND(J$3 >= $V28, J$3 <= $W28), $H28, "") | K28: =IF(AND(K$3 >= $V28, K$3 <= $W28), $H28, "") | L28: =IF(AND(L$3 >= $V28, L$3 <= $W28), $H28, "") | M28: =IF(AND(M$3 >= $V28, M$3 <= $W28), $H28, "") | N28: =IF(AND(N$3 >= $V28, N$3 <= $W28), $H28, "") | O28: =IF(AND(O$3 >= $V28, O$3 <= $W28), $H28, "") | P28: =IF(AND(P$3 >= $V28, P$3 <= $W28), $H28, "") | ... T28: =IF(AND(T$3 >= $V28, T$3 <= $W28), $H28, "") -> 5 | U28: FALSE | V28: 46357 | W28: 46357 | X28: Q2 | Z28: NOT STARTED
A29: 26 | B29: Pembangunan Cafetaria, Nursery, dan Taman Cinta Keluarga | C29: 1 | D29: GPAN2 | E29: Pengadaan - Kons. Perancang | F29: KAK | G29: Pengadaan - Kons. Perancang | KAK | H29: 9 | I29: =IF(AND(I$3 >= $V29, I$3 <= $W29), $H29, "") | J29: =IF(AND(J$3 >= $V29, J$3 <= $W29), $H29, "") | K29: =IF(AND(K$3 >= $V29, K$3 <= $W29), $H29, "") | L29: =IF(AND(L$3 >= $V29, L$3 <= $W29), $H29, "") | M29: =IF(AND(M$3 >= $V29, M$3 <= $W29), $H29, "") -> 9 | N29: =IF(AND(N$3 >= $V29, N$3 <= $W29), $H29, "") -> 9 | O29: =IF(AND(O$3 >= $V29, O$3 <= $W29), $H29, "") -> 9 | P29: =IF(AND(P$3 >= $V29, P$3 <= $W29), $H29, "") | ... T29: =IF(AND(T$3 >= $V29, T$3 <= $W29), $H29, "") | U29: TRUE | V29: 46143 | W29: 46204 | X29: Q2 | Y29: 46167 | Z29: ON TRACK | AB29: 28/149/DPAN/M.01/B
A30: 27 | B30: Pembangunan Cafetaria, Nursery, dan Taman Cinta Keluarga | C30: 1 | D30: GPAN2 | E30: Pengadaan - Kons. MK | F30: KAK | G30: Pengadaan - Kons. MK | KAK | H30: 11 | I30: =IF(AND(I$3 >= $V30, I$3 <= $W30), $H30, "") | J30: =IF(AND(J$3 >= $V30, J$3 <= $W30), $H30, "") | K30: =IF(AND(K$3 >= $V30, K$3 <= $W30), $H30, "") | L30: =IF(AND(L$3 >= $V30, L$3 <= $W30), $H30, "") | M30: =IF(AND(M$3 >= $V30, M$3 <= $W30), $H30, "") | N30: =IF(AND(N$3 >= $V30, N$3 <= $W30), $H30, "") | O30: =IF(AND(O$3 >= $V30, O$3 <= $W30), $H30, "") | P30: =IF(AND(P$3 >= $V30, P$3 <= $W30), $H30, "") | ... T30: =IF(AND(T$3 >= $V30, T$3 <= $W30), $H30, "") -> 11 | U30: FALSE | V30: 46327 | W30: 46357 | X30: Q2 | Z30: NOT STARTED
A31: 28 | B31: Pembangunan Cafetaria, Nursery, dan Taman Cinta Keluarga | C31: 1 | D31: GPAN2 | E31: Pengadaan - Kons. Perancang | F31: SPPP | G31: Pengadaan - Kons. Perancang | SPPP | H31: 10 | I31: =IF(AND(I$3 >= $V31, I$3 <= $W31), $H31, "") | J31: =IF(AND(J$3 >= $V31, J$3 <= $W31), $H31, "") | K31: =IF(AND(K$3 >= $V31, K$3 <= $W31), $H31, "") | L31: =IF(AND(L$3 >= $V31, L$3 <= $W31), $H31, "") | M31: =IF(AND(M$3 >= $V31, M$3 <= $W31), $H31, "") | N31: =IF(AND(N$3 >= $V31, N$3 <= $W31), $H31, "") | O31: =IF(AND(O$3 >= $V31, O$3 <= $W31), $H31, "") | P31: =IF(AND(P$3 >= $V31, P$3 <= $W31), $H31, "") -> 10 | ... T31: =IF(AND(T$3 >= $V31, T$3 <= $W31), $H31, "") -> 10 | U31: FALSE | V31: 46235 | W31: 46357 | X31: Q2 | Z31: BEHIND
A32: 29 | B32: Pembangunan DKW Sumut | C32: 1 | D32: GPAN2 | E32: Pra Pembangunan dan Pra Pengadaan | F32: RBT | G32: Pra Pembangunan dan Pra Pengadaan | RBT | H32: 5 | I32: =IF(AND(I$3 >= $V32, I$3 <= $W32), $H32, "") | J32: =IF(AND(J$3 >= $V32, J$3 <= $W32), $H32, "") | K32: =IF(AND(K$3 >= $V32, K$3 <= $W32), $H32, "") | L32: =IF(AND(L$3 >= $V32, L$3 <= $W32), $H32, "") | M32: =IF(AND(M$3 >= $V32, M$3 <= $W32), $H32, "") | N32: =IF(AND(N$3 >= $V32, N$3 <= $W32), $H32, "") -> 5 | O32: =IF(AND(O$3 >= $V32, O$3 <= $W32), $H32, "") | P32: =IF(AND(P$3 >= $V32, P$3 <= $W32), $H32, "") | ... T32: =IF(AND(T$3 >= $V32, T$3 <= $W32), $H32, "") | U32: TRUE | V32: 46174 | W32: 46174 | X32: Q1 | Y32: 46175 | Z32: ON TRACK
A33: 30 | B33: Pembangunan DKW Sumut | C33: 1 | D33: GPAN2 | E33: Pra Pembangunan dan Pra Pengadaan | F33: RPP | G33: Pra Pembangunan dan Pra Pengadaan | RPP | H33: 4 | I33: =IF(AND(I$3 >= $V33, I$3 <= $W33), $H33, "") | J33: =IF(AND(J$3 >= $V33, J$3 <= $W33), $H33, "") | K33: =IF(AND(K$3 >= $V33, K$3 <= $W33), $H33, "") | L33: =IF(AND(L$3 >= $V33, L$3 <= $W33), $H33, "") | M33: =IF(AND(M$3 >= $V33, M$3 <= $W33), $H33, "") | N33: =IF(AND(N$3 >= $V33, N$3 <= $W33), $H33, "") | O33: =IF(AND(O$3 >= $V33, O$3 <= $W33), $H33, "") | P33: =IF(AND(P$3 >= $V33, P$3 <= $W33), $H33, "") | ... T33: =IF(AND(T$3 >= $V33, T$3 <= $W33), $H33, "") | U33: FALSE | V33: 46266 | W33: 46266 | X33: Q1 | Z33: ON TRACK
A34: 31 | B34: Pembangunan DKW Sumut | C34: 1 | D34: GPAN2 | E34: Pra Pembangunan dan Pra Pengadaan | F34: RBTek | G34: Pra Pembangunan dan Pra Pengadaan | RBTek | H34: 6 | I34: =IF(AND(I$3 >= $V34, I$3 <= $W34), $H34, "") | J34: =IF(AND(J$3 >= $V34, J$3 <= $W34), $H34, "") | K34: =IF(AND(K$3 >= $V34, K$3 <= $W34), $H34, "") | L34: =IF(AND(L$3 >= $V34, L$3 <= $W34), $H34, "") | M34: =IF(AND(M$3 >= $V34, M$3 <= $W34), $H34, "") | N34: =IF(AND(N$3 >= $V34, N$3 <= $W34), $H34, "") | O34: =IF(AND(O$3 >= $V34, O$3 <= $W34), $H34, "") | P34: =IF(AND(P$3 >= $V34, P$3 <= $W34), $H34, "") | ... T34: =IF(AND(T$3 >= $V34, T$3 <= $W34), $H34, "") -> 6 | U34: FALSE | V34: 46357 | W34: 46357 | X34: Q1 | Z34: NOT STARTED
A35: 32 | B35: Pembangunan DKW Sumut | C35: 1 | D35: GPAN2 | E35: Pengadaan - Kons. MK | F35: KAK | G35: Pengadaan - Kons. MK | KAK | H35: 11 | I35: =IF(AND(I$3 >= $V35, I$3 <= $W35), $H35, "") | J35: =IF(AND(J$3 >= $V35, J$3 <= $W35), $H35, "") | K35: =IF(AND(K$3 >= $V35, K$3 <= $W35), $H35, "") | L35: =IF(AND(L$3 >= $V35, L$3 <= $W35), $H35, "") | M35: =IF(AND(M$3 >= $V35, M$3 <= $W35), $H35, "") | N35: =IF(AND(N$3 >= $V35, N$3 <= $W35), $H35, "") | O35: =IF(AND(O$3 >= $V35, O$3 <= $W35), $H35, "") | P35: =IF(AND(P$3 >= $V35, P$3 <= $W35), $H35, "") | ... T35: =IF(AND(T$3 >= $V35, T$3 <= $W35), $H35, "") | U35: FALSE | V35: 46296 | W35: 46327 | X35: Q1 | Z35: NOT STARTED
A36: 33 | B36: Pembangunan DKW Sumut | C36: 1 | D36: GPAN2 | E36: Pengadaan - Kontraktor | F36: KAK | G36: Pengadaan - Kontraktor | KAK | H36: 7 | I36: =IF(AND(I$3 >= $V36, I$3 <= $W36), $H36, "") | J36: =IF(AND(J$3 >= $V36, J$3 <= $W36), $H36, "") | K36: =IF(AND(K$3 >= $V36, K$3 <= $W36), $H36, "") | L36: =IF(AND(L$3 >= $V36, L$3 <= $W36), $H36, "") | M36: =IF(AND(M$3 >= $V36, M$3 <= $W36), $H36, "") | N36: =IF(AND(N$3 >= $V36, N$3 <= $W36), $H36, "") | O36: =IF(AND(O$3 >= $V36, O$3 <= $W36), $H36, "") | P36: =IF(AND(P$3 >= $V36, P$3 <= $W36), $H36, "") | ... T36: =IF(AND(T$3 >= $V36, T$3 <= $W36), $H36, "") -> 7 | U36: FALSE | V36: 46357 | W36: 46357 | X36: Q1 | Z36: NOT STARTED
A37: 34 | B37: Pembangunan DKW Sumut | C37: 1 | D37: GPAN2 | E37: Pengadaan - Kons. MK | F37: SPPP | G37: Pengadaan - Kons. MK | SPPP | H37: 12 | I37: =IF(AND(I$3 >= $V37, I$3 <= $W37), $H37, "") | J37: =IF(AND(J$3 >= $V37, J$3 <= $W37), $H37, "") | K37: =IF(AND(K$3 >= $V37, K$3 <= $W37), $H37, "") | L37: =IF(AND(L$3 >= $V37, L$3 <= $W37), $H37, "") | M37: =IF(AND(M$3 >= $V37, M$3 <= $W37), $H37, "") | N37: =IF(AND(N$3 >= $V37, N$3 <= $W37), $H37, "") | O37: =IF(AND(O$3 >= $V37, O$3 <= $W37), $H37, "") | P37: =IF(AND(P$3 >= $V37, P$3 <= $W37), $H37, "") | ... T37: =IF(AND(T$3 >= $V37, T$3 <= $W37), $H37, "") -> 12 | U37: FALSE | V37: 46357 | W37: 46357 | X37: Q1 | Z37: NOT STARTED
A38: 35 | B38: Pembangunan KPw Jambi | C38: 1 | D38: GPAN2 | E38: Implementasi | F38: Pembangunan Fisik | G38: Implementasi | Pembangunan Fisik | H38: 1 | I38: =IF(AND(I$3 >= $V38, I$3 <= $W38), $H38, "") -> 1 | J38: =IF(AND(J$3 >= $V38, J$3 <= $W38), $H38, "") -> 1 | K38: =IF(AND(K$3 >= $V38, K$3 <= $W38), $H38, "") -> 1 | L38: =IF(AND(L$3 >= $V38, L$3 <= $W38), $H38, "") -> 1 | M38: =IF(AND(M$3 >= $V38, M$3 <= $W38), $H38, "") -> 1 | N38: =IF(AND(N$3 >= $V38, N$3 <= $W38), $H38, "") -> 1 | O38: =IF(AND(O$3 >= $V38, O$3 <= $W38), $H38, "") -> 1 | P38: =IF(AND(P$3 >= $V38, P$3 <= $W38), $H38, "") -> 1 | ... T38: =IF(AND(T$3 >= $V38, T$3 <= $W38), $H38, "") -> 1 | U38: TRUE | V38: 46023 | W38: 46357 | X38: Q1 | Z38: ON TRACK
A39: 36 | B39: Pembangunan KPw Sulawesi Tengah | C39: 1 | D39: GPAN1 | E39: Pra Pembangunan dan Pra Pengadaan | F39: RPP | G39: Pra Pembangunan dan Pra Pengadaan | RPP | H39: 4 | I39: =IF(AND(I$3 >= $V39, I$3 <= $W39), $H39, "") | J39: =IF(AND(J$3 >= $V39, J$3 <= $W39), $H39, "") | K39: =IF(AND(K$3 >= $V39, K$3 <= $W39), $H39, "") | L39: =IF(AND(L$3 >= $V39, L$3 <= $W39), $H39, "") | M39: =IF(AND(M$3 >= $V39, M$3 <= $W39), $H39, "") | N39: =IF(AND(N$3 >= $V39, N$3 <= $W39), $H39, "") -> 4 | O39: =IF(AND(O$3 >= $V39, O$3 <= $W39), $H39, "") | P39: =IF(AND(P$3 >= $V39, P$3 <= $W39), $H39, "") | ... T39: =IF(AND(T$3 >= $V39, T$3 <= $W39), $H39, "") | U39: TRUE | V39: 46174 | W39: 46174 | X39: Q1 | Y39: 46255 | Z39: ON TRACK | AC39: sulteng tanpa rbt
A40: 37 | B40: Pembangunan KPw Sulawesi Tengah | C40: 1 | D40: GPAN1 | E40: Pra Pembangunan dan Pra Pengadaan | F40: RBTek | G40: Pra Pembangunan dan Pra Pengadaan | RBTek | H40: 6 | I40: =IF(AND(I$3 >= $V40, I$3 <= $W40), $H40, "") | J40: =IF(AND(J$3 >= $V40, J$3 <= $W40), $H40, "") | K40: =IF(AND(K$3 >= $V40, K$3 <= $W40), $H40, "") | L40: =IF(AND(L$3 >= $V40, L$3 <= $W40), $H40, "") | M40: =IF(AND(M$3 >= $V40, M$3 <= $W40), $H40, "") | N40: =IF(AND(N$3 >= $V40, N$3 <= $W40), $H40, "") | O40: =IF(AND(O$3 >= $V40, O$3 <= $W40), $H40, "") | P40: =IF(AND(P$3 >= $V40, P$3 <= $W40), $H40, "") | ... T40: =IF(AND(T$3 >= $V40, T$3 <= $W40), $H40, "") | U40: FALSE | V40: 46266 | W40: 46266 | X40: Q1 | Z40: ON TRACK
...
